<?xml version="1.0" encoding="utf-8"?>
<!-- This URDF was automatically created by SolidWorks to URDF Exporter! Originally created by Stephen Brawner (brawner@gmail.com) 
     Commit Version: 1.6.0-4-g7f85cfe  Build Version: 1.6.7995.38578
     For more information, please see http://wiki.ros.org/sw_urdf_exporter -->
<robot xmlns:xacro="http://ros.org/wiki/xacro" name="sizu">
  <!-- 过渡用 base（很小的可视box，不参与物理） -->
  <link name="map">
    <visual>
      <origin xyz="0.0 0.0 0.0" rpy="0.0 0.0 0.0" />
      <geometry>
        <box size="0.001 0.001 0.001"/>
      </geometry>
    </visual>
  </link>

  <joint name="map_joint" type="fixed">
    <parent link="map"/>
    <child link="base_link"/>
    <origin xyz="0.0 0.0 0.0" rpy="0.0 0.0 0.0"/>
  </joint>

  <!-- 机身 base_link -->
   <link name="base_link">
    <inertial>
      <origin xyz="0 0 0" rpy="0 0 0" />
      <mass value="3.0" />
      <inertia ixx="0.015" ixy="0.0" ixz="0.0" iyy="0.02" iyz="0.0" izz="0.03" />
    </inertial>
    <visual>
      <origin xyz="0 0 0" rpy="0 0 0" />
      <geometry>
        <mesh filename="package://sizu_gazebo/meshes/base_link.STL" />
      </geometry>
      <material name="">
        <color rgba="1 1 1 0.5" />
      </material>
    </visual>
    <collision>
      <origin xyz="0 0 0" rpy="0 0 0" />
      <geometry>
        <box size="0.1705 0.1555 0.05"/>
      </geometry>
    </collision>
  </link>

 <link name="lidar_link">
    <visual>
      <origin xyz="0.01 0 -0.02" rpy="0 0 0" />
      <geometry>
        <cylinder length="0.04" radius="0.02"/>
      </geometry>
      <material name="">
        <color rgba="0.2 0.2 0.2 1" />
      </material>
    </visual>
    <collision>
      <origin xyz="0.01 0 -0.02" rpy="0 0 0" />
      <geometry>
        <cylinder length="0.04" radius="0.02"/>
      </geometry>
    </collision>
  </link>

  <joint name="lidar_joint" type="fixed">
    <origin xyz="0.1 0 0.08" rpy="0 0 0" />
    <parent link="base_link" />
    <child link="lidar_link" />
    <axis xyz="0 0 0" />
  </joint>


  <link name="coxa_FL">
    <inertial>
      <origin xyz="0.04 0 0" rpy="0 0 0" />
      <mass value="0.1" />
      <inertia ixx="0.0001" ixy="0.0" ixz="0.0" iyy="0.0001" iyz="0.0" izz="0.0001" />
    </inertial>
    <visual>
      <origin xyz="0 0 0" rpy="0 0 0" />
      <geometry>
        <mesh filename="package://sizu_gazebo/meshes/coxa_FL.STL" />
      </geometry>
      <material name="">
        <color rgba="1 1 1 1" />
      </material>
    </visual>
    <collision>
      <origin xyz="0.0 0 -0.02" rpy="0 0 0" />
      <geometry>
        <cylinder length="0.02" radius="0.02"/>
      </geometry>
    </collision>
  </link>
  <joint
    name="coxa_joint_FL"
    type="continuous">
    <origin
      xyz="0.10275 0.11525 0"
      rpy="0 0 0" />
    <parent
      link="base_link" />
    <child
      link="coxa_FL" />
    <axis
      xyz="0 0 1" />
    <limit effort="50" velocity="2"/>
  </joint>
  <link name="femur_FL">
    <inertial>
      <origin xyz="0.08 0 0" rpy="0 0 0" />
      <mass value="0.5" />
      <inertia ixx="0.003" ixy="0.0" ixz="0.0" iyy="0.003" iyz="0.0" izz="0.003" />
    </inertial>
    <visual>
      <origin xyz="0 0 0" rpy="0 0 0" />
      <geometry>
        <mesh filename="package://sizu_gazebo/meshes/femur_FL.STL" />
      </geometry>
      <material name="">
        <color rgba="0.8 0.8 0.8 1" />
      </material>
    </visual>
    <collision>
      <origin xyz="0.06 0 -0.02" rpy="0 0 0" />
      <geometry>
        <box size="0.12 0.04 0.04"/>
      </geometry>
    </collision>
  </link>
  <joint
    name="femur_joint_FL"
    type="continuous">
    <origin
      xyz="0.0635321928743235 0.0437332030011003 0.0255"
      rpy="1.5707963267949 0 0.78539816339745" />
    <parent
      link="coxa_FL" />
    <child
      link="femur_FL" />
    <axis
      xyz="0 0 -1" />
    <limit effort="50" velocity="2"/>
  </joint>
  <link name="tibia_FL">
    <inertial>
      <origin xyz="0.18 0 0" rpy="0 0 0" />
      <mass value="0.2" />
      <inertia ixx="0.002" ixy="0.0" ixz="0.0" iyy="0.002" iyz="0.0" izz="0.002" />
    </inertial>
    <visual>
      <origin xyz="0 0 0" rpy="0 0 0" />
      <geometry>
        <mesh filename="package://sizu_gazebo/meshes/tibia_FL.STL" />
      </geometry>
      <material name="">
        <color rgba="0.2 0.2 0.2 1" />
      </material>
    </visual>
    <collision>
      <origin xyz="0.18 0 0" rpy="0 0 0" />
      <geometry>
        <box size="0.26 0.03 0.03"/>
      </geometry>
    </collision>
  </link>
  <joint
    name="tibia_joint_FL"
    type="continuous">
    <origin
      xyz="0.164 0 0"
      rpy="0 0 0" />
    <parent
      link="femur_FL" />
    <child
      link="tibia_FL" />
    <axis
      xyz="0 0 -1" />
    <limit effort="50" velocity="2"/>
  </joint>
  <link name="coxa_RL">
    <inertial>
      <origin xyz="0.04 0 0" rpy="0 0 0" />
      <mass value="0.1" />
      <inertia ixx="0.0001" ixy="0.0" ixz="0.0" iyy="0.0001" iyz="0.0" izz="0.0001" />
    </inertial>
    <visual>
      <origin xyz="0 0 0" rpy="0 0 0" />
      <geometry>
        <mesh filename="package://sizu_gazebo/meshes/coxa_RL.STL" />
      </geometry>
      <material name="">
        <color rgba="1 1 1 1" />
      </material>
    </visual>
    <collision>
      <origin xyz="0.0 0 -0.02" rpy="0 0 0" />
      <geometry>
        <cylinder length="0.02" radius="0.02"/>
      </geometry>
    </collision>
  </link>
  <joint
    name="coxa_joint_RL"
    type="continuous">
    <origin
      xyz="-0.10275 0.11525 0"
      rpy="0 0 0" />
    <parent
      link="base_link" />
    <child
      link="coxa_RL" />
    <axis
      xyz="0 0 1" />
    <limit effort="50" velocity="2"/>
  </joint>
  <link name="femur_RL">
    <inertial>
      <origin xyz="0.08 0 0" rpy="0 0 0" />
      <mass value="0.5" />
      <inertia ixx="0.003" ixy="0.0" ixz="0.0" iyy="0.003" iyz="0.0" izz="0.003" />
    </inertial>
    <visual>
      <origin xyz="0 0 0" rpy="0 0 0" />
      <geometry>
        <mesh filename="package://sizu_gazebo/meshes/femur_RL.STL" />
      </geometry>
      <material name="">
        <color rgba="0.8 0.8 0.8 1" />
      </material>
    </visual>
    <collision>
      <origin xyz="0.06 0 -0.02" rpy="0 0 0" />
      <geometry>
        <box size="0.12 0.04 0.04"/>
      </geometry>
    </collision>
  </link>
  <joint
    name="femur_joint_RL"
    type="continuous">
    <origin
      xyz="-0.0635321928743236 0.0437332030011001 0.0255"
      rpy="-1.5707963267949 0 2.35619449019235" />
    <parent
      link="coxa_RL" />
    <child
      link="femur_RL" />
    <axis
      xyz="0 0 -1" />
    <limit effort="50" velocity="2"/>
  </joint>
  <link name="tibia_RL">
    <inertial>
      <origin xyz="0.18 0 0" rpy="0 0 0" />
      <mass value="0.2" />
      <inertia ixx="0.002" ixy="0.0" ixz="0.0" iyy="0.002" iyz="0.0" izz="0.002" />
    </inertial>
    <visual>
      <origin xyz="0 0 0" rpy="0 0 0" />
      <geometry>
        <mesh filename="package://sizu_gazebo/meshes/tibia_RL.STL" />
      </geometry>
      <material name="">
        <color rgba="0.2 0.2 0.2 1" />
      </material>
    </visual>
    <collision>
      <origin xyz="0.18 0 0" rpy="0 0 0" />
      <geometry>
        <box size="0.26 0.03 0.03"/>
      </geometry>
    </collision>
  </link>
  <joint
    name="tibia_joint_RL"
    type="continuous">
    <origin
      xyz="0.164 0 0"
      rpy="0 0 0" />
    <parent
      link="femur_RL" />
    <child
      link="tibia_RL" />
    <axis
      xyz="0 0 -1" />
    <limit effort="50" velocity="2"/>
  </joint>
  <link name="coxa_FR">
    <inertial>
      <origin xyz="0.04 0 0" rpy="0 0 0" />
      <mass value="0.1" />
      <inertia ixx="0.0001" ixy="0.0" ixz="0.0" iyy="0.0001" iyz="0.0" izz="0.0001" />
    </inertial>
    <visual>
      <origin xyz="0 0 0" rpy="0 0 0" />
      <geometry>
        <mesh filename="package://sizu_gazebo/meshes/coxa_FR.STL" />
      </geometry>
      <material name="">
        <color rgba="1 1 1 1" />
      </material>
    </visual>
    <collision>
      <origin xyz="0.0 0 -0.02" rpy="0 0 0" />
      <geometry>
        <cylinder length="0.02" radius="0.02"/>
      </geometry>
    </collision>
  </link>
  <joint
    name="coxa_joint_FR"
    type="continuous">
    <origin
      xyz="0.10275 -0.11525 0"
      rpy="0 0 0" />
    <parent
      link="base_link" />
    <child
      link="coxa_FR" />
    <axis
      xyz="0 0 1" />
    <limit effort="50" velocity="2"/>
  </joint>
  <link name="femur_FR">
    <inertial>
      <origin xyz="0.08 0 0" rpy="0 0 0" />
      <mass value="0.5" />
      <inertia ixx="0.003" ixy="0.0" ixz="0.0" iyy="0.003" iyz="0.0" izz="0.003" />
    </inertial>
    <visual>
      <origin xyz="0 0 0" rpy="0 0 0" />
      <geometry>
        <mesh filename="package://sizu_gazebo/meshes/femur_FR.STL" />
      </geometry>
      <material name="">
        <color rgba="0.8 0.8 0.8 1" />
      </material>
    </visual>
    <collision>
      <origin xyz="0.06 0 -0.02" rpy="0 0 0" />
      <geometry>
        <box size="0.12 0.04 0.04"/>
      </geometry>
    </collision>
  </link>
  <joint
    name="femur_joint_FR"
    type="continuous">
    <origin
      xyz="0.0635321928743236 -0.0437332030011001 0.0255000000000001"
      rpy="-1.5707963267949 0 -0.785398163397447" />
    <parent
      link="coxa_FR" />
    <child
      link="femur_FR" />
    <axis
      xyz="0 0 -1" />
    <limit effort="50" velocity="2"/>
  </joint>
  <link name="tibia_FR">
    <inertial>
      <origin xyz="0.18 0 0" rpy="0 0 0" />
      <mass value="0.2" />
      <inertia ixx="0.002" ixy="0.0" ixz="0.0" iyy="0.002" iyz="0.0" izz="0.002" />
    </inertial>
    <visual>
      <origin xyz="0 0 0" rpy="0 0 0" />
      <geometry>
        <mesh filename="package://sizu_gazebo/meshes/tibia_FR.STL" />
      </geometry>
      <material name="">
        <color rgba="0.2 0.2 0.2 1" />
      </material>
    </visual>
    <collision>
      <origin xyz="0.18 0 0" rpy="0 0 0" />
      <geometry>
        <box size="0.26 0.03 0.03"/>
      </geometry>
    </collision>
  </link>
  <joint
    name="tibia_joint_FR"
    type="continuous">
    <origin
      xyz="0.164 0 0"
      rpy="0 0 0" />
    <parent
      link="femur_FR" />
    <child
      link="tibia_FR" />
    <axis
      xyz="0 0 -1" />
    <limit effort="50" velocity="2"/>
  </joint>
  <link name="coxa_RR">
    <inertial>
      <origin xyz="0.04 0 0" rpy="0 0 0" />
      <mass value="0.1" />
      <inertia ixx="0.0001" ixy="0.0" ixz="0.0" iyy="0.0001" iyz="0.0" izz="0.0001" />
    </inertial>
    <visual>
      <origin xyz="0 0 0" rpy="0 0 0" />
      <geometry>
        <mesh filename="package://sizu_gazebo/meshes/coxa_RR.STL" />
      </geometry>
      <material name="">
        <color rgba="1 1 1 1" />
      </material>
    </visual>
    <collision>
      <origin xyz="0.0 0 -0.02" rpy="0 0 0" />
      <geometry>
        <cylinder length="0.02" radius="0.02"/>
      </geometry>
    </collision>
  </link>
  <joint
    name="coxa_joint_RR"
    type="continuous">
    <origin
      xyz="-0.10275 -0.11525 0"
      rpy="0 0 0" />
    <parent
      link="base_link" />
    <child
      link="coxa_RR" />
    <axis
      xyz="0 0 1" />
    <limit effort="50" velocity="2"/>
  </joint>
  <link name="femur_RR">
    <inertial>
      <origin xyz="0.08 0 0" rpy="0 0 0" />
      <mass value="0.5" />
      <inertia ixx="0.003" ixy="0.0" ixz="0.0" iyy="0.003" iyz="0.0" izz="0.003" />
    </inertial>
    <visual>
      <origin xyz="0 0 0" rpy="0 0 0" />
      <geometry>
        <mesh filename="package://sizu_gazebo/meshes/femur_RR.STL" />
      </geometry>
      <material name="">
        <color rgba="0.8 0.8 0.8 1" />
      </material>
    </visual>
    <collision>
      <origin xyz="0.06 0 -0.02" rpy="0 0 0" />
      <geometry>
        <box size="0.12 0.04 0.04"/>
      </geometry>
    </collision>
  </link>
  <joint
    name="femur_joint_RR"
    type="continuous">
    <origin
      xyz="-0.0635321928743236 -0.0437332030011001 0.0255"
      rpy="1.5707963267949 0 -2.35619449019235" />
    <parent
      link="coxa_RR" />
    <child
      link="femur_RR" />
    <axis
      xyz="0 0 -1" />
    <limit effort="50" velocity="2"/>
  </joint>
  <link name="tibia_RR">
    <inertial>
      <origin xyz="0.18 0 0" rpy="0 0 0" />
      <mass value="0.2" />
      <inertia ixx="0.002" ixy="0.0" ixz="0.0" iyy="0.002" iyz="0.0" izz="0.002" />
    </inertial>
    <visual>
      <origin xyz="0 0 0" rpy="0 0 0" />
      <geometry>
        <mesh filename="package://sizu_gazebo/meshes/tibia_RR.STL" />
      </geometry>
      <material name="">
        <color rgba="0.2 0.2 0.2 1" />
      </material>
    </visual>
    <collision>
      <origin xyz="0.18 0 0" rpy="0 0 0" />
      <geometry>
        <box size="0.26 0.03 0.03"/>
      </geometry>
    </collision>
  </link>
  <joint
    name="tibia_joint_RR"
    type="continuous">
    <origin
      xyz="0.164 0 0"
      rpy="0 0 0" />
    <parent
      link="femur_RR" />
    <child
      link="tibia_RR" />
    <axis
      xyz="0 0 -1" />
    <limit effort="50" velocity="2"/>
  </joint>



</robot>